INFO:__main__:None
INFO:__main__:None
ERROR:discord.ext.commands.bot:Ignoring exception in command stats
Traceback (most recent call last):
  File "C:\Users\cmerr\AppData\Local\Packages\PythonSoftwareFoundation.Python.3.12_qbz5n2kfra8p0\LocalCache\local-packages\Python312\site-packages\discord\ext\commands\core.py", line 235, in wrapped
    ret = await coro(*args, **kwargs)
          ^^^^^^^^^^^^^^^^^^^^^^^^^^^
  File "C:\Users\cmerr\PycharmProjects\LeagueBot\src\bot.py", line 62, in fetch_player_stats
    output = format_ranked_stats(ranked_stats)
             ^^^^^^^^^^^^^^^^^^^^^^^^^^^^^^^^^
  File "C:\Users\cmerr\PycharmProjects\LeagueBot\src\utils\data_formatter.py", line 7, in format_ranked_stats
    for queue in ranked_stats:
                 ^^^^^^^^^^^^
TypeError: 'NoneType' object is not iterable

The above exception was the direct cause of the following exception:

Traceback (most recent call last):
  File "C:\Users\cmerr\AppData\Local\Packages\PythonSoftwareFoundation.Python.3.12_qbz5n2kfra8p0\LocalCache\local-packages\Python312\site-packages\discord\ext\commands\bot.py", line 1366, in invoke
    await ctx.command.invoke(ctx)
  File "C:\Users\cmerr\AppData\Local\Packages\PythonSoftwareFoundation.Python.3.12_qbz5n2kfra8p0\LocalCache\local-packages\Python312\site-packages\discord\ext\commands\core.py", line 1029, in invoke
    await injected(*ctx.args, **ctx.kwargs)  # type: ignore
    ^^^^^^^^^^^^^^^^^^^^^^^^^^^^^^^^^^^^^^^
  File "C:\Users\cmerr\AppData\Local\Packages\PythonSoftwareFoundation.Python.3.12_qbz5n2kfra8p0\LocalCache\local-packages\Python312\site-packages\discord\ext\commands\core.py", line 244, in wrapped
    raise CommandInvokeError(exc) from exc
discord.ext.commands.errors.CommandInvokeError: Command raised an exception: TypeError: 'NoneType' object is not iterable
INFO:__main__:None
INFO:__main__:None
ERROR:discord.ext.commands.bot:Ignoring exception in command stats
Traceback (most recent call last):
  File "C:\Users\cmerr\AppData\Local\Packages\PythonSoftwareFoundation.Python.3.12_qbz5n2kfra8p0\LocalCache\local-packages\Python312\site-packages\discord\ext\commands\core.py", line 235, in wrapped
    ret = await coro(*args, **kwargs)
          ^^^^^^^^^^^^^^^^^^^^^^^^^^^
  File "C:\Users\cmerr\PycharmProjects\LeagueBot\src\bot.py", line 62, in fetch_player_stats
    output = format_ranked_stats(ranked_stats)
             ^^^^^^^^^^^^^^^^^^^^^^^^^^^^^^^^^
  File "C:\Users\cmerr\PycharmProjects\LeagueBot\src\utils\data_formatter.py", line 7, in format_ranked_stats
    for queue in ranked_stats:
                 ^^^^^^^^^^^^
TypeError: 'NoneType' object is not iterable

The above exception was the direct cause of the following exception:

Traceback (most recent call last):
  File "C:\Users\cmerr\AppData\Local\Packages\PythonSoftwareFoundation.Python.3.12_qbz5n2kfra8p0\LocalCache\local-packages\Python312\site-packages\discord\ext\commands\bot.py", line 1366, in invoke
    await ctx.command.invoke(ctx)
  File "C:\Users\cmerr\AppData\Local\Packages\PythonSoftwareFoundation.Python.3.12_qbz5n2kfra8p0\LocalCache\local-packages\Python312\site-packages\discord\ext\commands\core.py", line 1029, in invoke
    await injected(*ctx.args, **ctx.kwargs)  # type: ignore
    ^^^^^^^^^^^^^^^^^^^^^^^^^^^^^^^^^^^^^^^
  File "C:\Users\cmerr\AppData\Local\Packages\PythonSoftwareFoundation.Python.3.12_qbz5n2kfra8p0\LocalCache\local-packages\Python312\site-packages\discord\ext\commands\core.py", line 244, in wrapped
    raise CommandInvokeError(exc) from exc
discord.ext.commands.errors.CommandInvokeError: Command raised an exception: TypeError: 'NoneType' object is not iterable
INFO:__main__:None
INFO:__main__:None
ERROR:discord.ext.commands.bot:Ignoring exception in command stats
Traceback (most recent call last):
  File "C:\Users\cmerr\AppData\Local\Packages\PythonSoftwareFoundation.Python.3.12_qbz5n2kfra8p0\LocalCache\local-packages\Python312\site-packages\discord\ext\commands\core.py", line 235, in wrapped
    ret = await coro(*args, **kwargs)
          ^^^^^^^^^^^^^^^^^^^^^^^^^^^
  File "C:\Users\cmerr\PycharmProjects\LeagueBot\src\bot.py", line 62, in fetch_player_stats
    output = format_ranked_stats(ranked_stats)
             ^^^^^^^^^^^^^^^^^^^^^^^^^^^^^^^^^
  File "C:\Users\cmerr\PycharmProjects\LeagueBot\src\utils\data_formatter.py", line 7, in format_ranked_stats
    for queue in ranked_stats:
                 ^^^^^^^^^^^^
TypeError: 'NoneType' object is not iterable

The above exception was the direct cause of the following exception:

Traceback (most recent call last):
  File "C:\Users\cmerr\AppData\Local\Packages\PythonSoftwareFoundation.Python.3.12_qbz5n2kfra8p0\LocalCache\local-packages\Python312\site-packages\discord\ext\commands\bot.py", line 1366, in invoke
    await ctx.command.invoke(ctx)
  File "C:\Users\cmerr\AppData\Local\Packages\PythonSoftwareFoundation.Python.3.12_qbz5n2kfra8p0\LocalCache\local-packages\Python312\site-packages\discord\ext\commands\core.py", line 1029, in invoke
    await injected(*ctx.args, **ctx.kwargs)  # type: ignore
    ^^^^^^^^^^^^^^^^^^^^^^^^^^^^^^^^^^^^^^^
  File "C:\Users\cmerr\AppData\Local\Packages\PythonSoftwareFoundation.Python.3.12_qbz5n2kfra8p0\LocalCache\local-packages\Python312\site-packages\discord\ext\commands\core.py", line 244, in wrapped
    raise CommandInvokeError(exc) from exc
discord.ext.commands.errors.CommandInvokeError: Command raised an exception: TypeError: 'NoneType' object is not iterable
INFO:__main__:None
INFO:__main__:None
ERROR:discord.ext.commands.bot:Ignoring exception in command stats
Traceback (most recent call last):
  File "C:\Users\cmerr\AppData\Local\Packages\PythonSoftwareFoundation.Python.3.12_qbz5n2kfra8p0\LocalCache\local-packages\Python312\site-packages\discord\ext\commands\core.py", line 235, in wrapped
    ret = await coro(*args, **kwargs)
          ^^^^^^^^^^^^^^^^^^^^^^^^^^^
  File "C:\Users\cmerr\PycharmProjects\LeagueBot\src\bot.py", line 62, in fetch_player_stats
    output = format_ranked_stats(ranked_stats)
             ^^^^^^^^^^^^^^^^^^^^^^^^^^^^^^^^^
  File "C:\Users\cmerr\PycharmProjects\LeagueBot\src\utils\data_formatter.py", line 7, in format_ranked_stats
    for queue in ranked_stats:
                 ^^^^^^^^^^^^
TypeError: 'NoneType' object is not iterable

The above exception was the direct cause of the following exception:

Traceback (most recent call last):
  File "C:\Users\cmerr\AppData\Local\Packages\PythonSoftwareFoundation.Python.3.12_qbz5n2kfra8p0\LocalCache\local-packages\Python312\site-packages\discord\ext\commands\bot.py", line 1366, in invoke
    await ctx.command.invoke(ctx)
  File "C:\Users\cmerr\AppData\Local\Packages\PythonSoftwareFoundation.Python.3.12_qbz5n2kfra8p0\LocalCache\local-packages\Python312\site-packages\discord\ext\commands\core.py", line 1029, in invoke
    await injected(*ctx.args, **ctx.kwargs)  # type: ignore
    ^^^^^^^^^^^^^^^^^^^^^^^^^^^^^^^^^^^^^^^
  File "C:\Users\cmerr\AppData\Local\Packages\PythonSoftwareFoundation.Python.3.12_qbz5n2kfra8p0\LocalCache\local-packages\Python312\site-packages\discord\ext\commands\core.py", line 244, in wrapped
    raise CommandInvokeError(exc) from exc
discord.ext.commands.errors.CommandInvokeError: Command raised an exception: TypeError: 'NoneType' object is not iterable
INFO:__main__:None
INFO:__main__:None
ERROR:discord.ext.commands.bot:Ignoring exception in command stats
Traceback (most recent call last):
  File "C:\Users\cmerr\AppData\Local\Packages\PythonSoftwareFoundation.Python.3.12_qbz5n2kfra8p0\LocalCache\local-packages\Python312\site-packages\discord\ext\commands\core.py", line 235, in wrapped
    ret = await coro(*args, **kwargs)
          ^^^^^^^^^^^^^^^^^^^^^^^^^^^
  File "C:\Users\cmerr\PycharmProjects\LeagueBot\src\bot.py", line 62, in fetch_player_stats
    output = format_ranked_stats(ranked_stats)
             ^^^^^^^^^^^^^^^^^^^^^^^^^^^^^^^^^
  File "C:\Users\cmerr\PycharmProjects\LeagueBot\src\utils\data_formatter.py", line 7, in format_ranked_stats
    for queue in ranked_stats:
                 ^^^^^^^^^^^^
TypeError: 'NoneType' object is not iterable

The above exception was the direct cause of the following exception:

Traceback (most recent call last):
  File "C:\Users\cmerr\AppData\Local\Packages\PythonSoftwareFoundation.Python.3.12_qbz5n2kfra8p0\LocalCache\local-packages\Python312\site-packages\discord\ext\commands\bot.py", line 1366, in invoke
    await ctx.command.invoke(ctx)
  File "C:\Users\cmerr\AppData\Local\Packages\PythonSoftwareFoundation.Python.3.12_qbz5n2kfra8p0\LocalCache\local-packages\Python312\site-packages\discord\ext\commands\core.py", line 1029, in invoke
    await injected(*ctx.args, **ctx.kwargs)  # type: ignore
    ^^^^^^^^^^^^^^^^^^^^^^^^^^^^^^^^^^^^^^^
  File "C:\Users\cmerr\AppData\Local\Packages\PythonSoftwareFoundation.Python.3.12_qbz5n2kfra8p0\LocalCache\local-packages\Python312\site-packages\discord\ext\commands\core.py", line 244, in wrapped
    raise CommandInvokeError(exc) from exc
discord.ext.commands.errors.CommandInvokeError: Command raised an exception: TypeError: 'NoneType' object is not iterable
ERROR:discord.ext.commands.bot:Ignoring exception in command stats
Traceback (most recent call last):
  File "C:\Users\cmerr\AppData\Local\Packages\PythonSoftwareFoundation.Python.3.12_qbz5n2kfra8p0\LocalCache\local-packages\Python312\site-packages\urllib3\util\url.py", line 425, in parse_url
    host, port = _HOST_PORT_RE.match(host_port).groups()  # type: ignore[union-attr]
                 ^^^^^^^^^^^^^^^^^^^^^^^^^^^^^^^^^^^^^
AttributeError: 'NoneType' object has no attribute 'groups'

The above exception was the direct cause of the following exception:

Traceback (most recent call last):
  File "C:\Users\cmerr\AppData\Local\Packages\PythonSoftwareFoundation.Python.3.12_qbz5n2kfra8p0\LocalCache\local-packages\Python312\site-packages\requests\models.py", line 433, in prepare_url
    scheme, auth, host, port, path, query, fragment = parse_url(url)
                                                      ^^^^^^^^^^^^^^
  File "C:\Users\cmerr\AppData\Local\Packages\PythonSoftwareFoundation.Python.3.12_qbz5n2kfra8p0\LocalCache\local-packages\Python312\site-packages\urllib3\util\url.py", line 451, in parse_url
    raise LocationParseError(source_url) from e
urllib3.exceptions.LocationParseError: Failed to parse: https://Please enter a region:.api.riotgames.com/riot/account/v1/accounts/by-riot-id/BELLA CIAOOOOO/NA1

During handling of the above exception, another exception occurred:

Traceback (most recent call last):
  File "C:\Users\cmerr\AppData\Local\Packages\PythonSoftwareFoundation.Python.3.12_qbz5n2kfra8p0\LocalCache\local-packages\Python312\site-packages\discord\ext\commands\core.py", line 235, in wrapped
    ret = await coro(*args, **kwargs)
          ^^^^^^^^^^^^^^^^^^^^^^^^^^^
  File "C:\Users\cmerr\PycharmProjects\LeagueBot\src\bot.py", line 55, in fetch_player_stats
    puuid = get_puuid(username, tag_line, region)
            ^^^^^^^^^^^^^^^^^^^^^^^^^^^^^^^^^^^^^
  File "C:\Users\cmerr\PycharmProjects\LeagueBot\src\utils\riot_api.py", line 12, in get_puuid
    response = requests.get(url, headers=headers)
               ^^^^^^^^^^^^^^^^^^^^^^^^^^^^^^^^^^
  File "C:\Users\cmerr\AppData\Local\Packages\PythonSoftwareFoundation.Python.3.12_qbz5n2kfra8p0\LocalCache\local-packages\Python312\site-packages\requests\api.py", line 73, in get
    return request("get", url, params=params, **kwargs)
           ^^^^^^^^^^^^^^^^^^^^^^^^^^^^^^^^^^^^^^^^^^^^
  File "C:\Users\cmerr\AppData\Local\Packages\PythonSoftwareFoundation.Python.3.12_qbz5n2kfra8p0\LocalCache\local-packages\Python312\site-packages\requests\api.py", line 59, in request
    return session.request(method=method, url=url, **kwargs)
           ^^^^^^^^^^^^^^^^^^^^^^^^^^^^^^^^^^^^^^^^^^^^^^^^^
  File "C:\Users\cmerr\AppData\Local\Packages\PythonSoftwareFoundation.Python.3.12_qbz5n2kfra8p0\LocalCache\local-packages\Python312\site-packages\requests\sessions.py", line 575, in request
    prep = self.prepare_request(req)
           ^^^^^^^^^^^^^^^^^^^^^^^^^
  File "C:\Users\cmerr\AppData\Local\Packages\PythonSoftwareFoundation.Python.3.12_qbz5n2kfra8p0\LocalCache\local-packages\Python312\site-packages\requests\sessions.py", line 484, in prepare_request
    p.prepare(
  File "C:\Users\cmerr\AppData\Local\Packages\PythonSoftwareFoundation.Python.3.12_qbz5n2kfra8p0\LocalCache\local-packages\Python312\site-packages\requests\models.py", line 367, in prepare
    self.prepare_url(url, params)
  File "C:\Users\cmerr\AppData\Local\Packages\PythonSoftwareFoundation.Python.3.12_qbz5n2kfra8p0\LocalCache\local-packages\Python312\site-packages\requests\models.py", line 435, in prepare_url
    raise InvalidURL(*e.args)
requests.exceptions.InvalidURL: Failed to parse: https://Please enter a region:.api.riotgames.com/riot/account/v1/accounts/by-riot-id/BELLA CIAOOOOO/NA1

The above exception was the direct cause of the following exception:

Traceback (most recent call last):
  File "C:\Users\cmerr\AppData\Local\Packages\PythonSoftwareFoundation.Python.3.12_qbz5n2kfra8p0\LocalCache\local-packages\Python312\site-packages\discord\ext\commands\bot.py", line 1366, in invoke
    await ctx.command.invoke(ctx)
  File "C:\Users\cmerr\AppData\Local\Packages\PythonSoftwareFoundation.Python.3.12_qbz5n2kfra8p0\LocalCache\local-packages\Python312\site-packages\discord\ext\commands\core.py", line 1029, in invoke
    await injected(*ctx.args, **ctx.kwargs)  # type: ignore
    ^^^^^^^^^^^^^^^^^^^^^^^^^^^^^^^^^^^^^^^
  File "C:\Users\cmerr\AppData\Local\Packages\PythonSoftwareFoundation.Python.3.12_qbz5n2kfra8p0\LocalCache\local-packages\Python312\site-packages\discord\ext\commands\core.py", line 244, in wrapped
    raise CommandInvokeError(exc) from exc
discord.ext.commands.errors.CommandInvokeError: Command raised an exception: InvalidURL: Failed to parse: https://Please enter a region:.api.riotgames.com/riot/account/v1/accounts/by-riot-id/BELLA CIAOOOOO/NA1
INFO:__main__:None
INFO:__main__:None
ERROR:discord.ext.commands.bot:Ignoring exception in command stats
Traceback (most recent call last):
  File "C:\Users\cmerr\AppData\Local\Packages\PythonSoftwareFoundation.Python.3.12_qbz5n2kfra8p0\LocalCache\local-packages\Python312\site-packages\discord\ext\commands\core.py", line 235, in wrapped
    ret = await coro(*args, **kwargs)
          ^^^^^^^^^^^^^^^^^^^^^^^^^^^
  File "C:\Users\cmerr\PycharmProjects\LeagueBot\src\bot.py", line 62, in fetch_player_stats
    output = format_ranked_stats(ranked_stats)
             ^^^^^^^^^^^^^^^^^^^^^^^^^^^^^^^^^
  File "C:\Users\cmerr\PycharmProjects\LeagueBot\src\utils\data_formatter.py", line 7, in format_ranked_stats
    for queue in ranked_stats:
                 ^^^^^^^^^^^^
TypeError: 'NoneType' object is not iterable

The above exception was the direct cause of the following exception:

Traceback (most recent call last):
  File "C:\Users\cmerr\AppData\Local\Packages\PythonSoftwareFoundation.Python.3.12_qbz5n2kfra8p0\LocalCache\local-packages\Python312\site-packages\discord\ext\commands\bot.py", line 1366, in invoke
    await ctx.command.invoke(ctx)
  File "C:\Users\cmerr\AppData\Local\Packages\PythonSoftwareFoundation.Python.3.12_qbz5n2kfra8p0\LocalCache\local-packages\Python312\site-packages\discord\ext\commands\core.py", line 1029, in invoke
    await injected(*ctx.args, **ctx.kwargs)  # type: ignore
    ^^^^^^^^^^^^^^^^^^^^^^^^^^^^^^^^^^^^^^^
  File "C:\Users\cmerr\AppData\Local\Packages\PythonSoftwareFoundation.Python.3.12_qbz5n2kfra8p0\LocalCache\local-packages\Python312\site-packages\discord\ext\commands\core.py", line 244, in wrapped
    raise CommandInvokeError(exc) from exc
discord.ext.commands.errors.CommandInvokeError: Command raised an exception: TypeError: 'NoneType' object is not iterable
INFO:__main__:None
INFO:__main__:None
ERROR:discord.ext.commands.bot:Ignoring exception in command stats
Traceback (most recent call last):
  File "C:\Users\cmerr\AppData\Local\Packages\PythonSoftwareFoundation.Python.3.12_qbz5n2kfra8p0\LocalCache\local-packages\Python312\site-packages\discord\ext\commands\core.py", line 235, in wrapped
    ret = await coro(*args, **kwargs)
          ^^^^^^^^^^^^^^^^^^^^^^^^^^^
  File "c:\Users\cmerr\PycharmProjects\LeagueBot\src\bot.py", line 62, in fetch_player_stats
    output = format_ranked_stats(ranked_stats)
             ^^^^^^^^^^^^^^^^^^^^^^^^^^^^^^^^^
  File "c:\Users\cmerr\PycharmProjects\LeagueBot\src\utils\data_formatter.py", line 7, in format_ranked_stats
    for queue in ranked_stats:
                 ^^^^^^^^^^^^
TypeError: 'NoneType' object is not iterable

The above exception was the direct cause of the following exception:

Traceback (most recent call last):
  File "C:\Users\cmerr\AppData\Local\Packages\PythonSoftwareFoundation.Python.3.12_qbz5n2kfra8p0\LocalCache\local-packages\Python312\site-packages\discord\ext\commands\bot.py", line 1366, in invoke
    await ctx.command.invoke(ctx)
  File "C:\Users\cmerr\AppData\Local\Packages\PythonSoftwareFoundation.Python.3.12_qbz5n2kfra8p0\LocalCache\local-packages\Python312\site-packages\discord\ext\commands\core.py", line 1029, in invoke
    await injected(*ctx.args, **ctx.kwargs)  # type: ignore
    ^^^^^^^^^^^^^^^^^^^^^^^^^^^^^^^^^^^^^^^
  File "C:\Users\cmerr\AppData\Local\Packages\PythonSoftwareFoundation.Python.3.12_qbz5n2kfra8p0\LocalCache\local-packages\Python312\site-packages\discord\ext\commands\core.py", line 244, in wrapped
    raise CommandInvokeError(exc) from exc
discord.ext.commands.errors.CommandInvokeError: Command raised an exception: TypeError: 'NoneType' object is not iterable
INFO:__main__:None
INFO:__main__:None
ERROR:discord.ext.commands.bot:Ignoring exception in command stats
Traceback (most recent call last):
  File "C:\Users\cmerr\AppData\Local\Packages\PythonSoftwareFoundation.Python.3.12_qbz5n2kfra8p0\LocalCache\local-packages\Python312\site-packages\discord\ext\commands\core.py", line 235, in wrapped
    ret = await coro(*args, **kwargs)
          ^^^^^^^^^^^^^^^^^^^^^^^^^^^
  File "C:\Users\cmerr\PycharmProjects\LeagueBot\src\bot.py", line 62, in fetch_player_stats
    output = format_ranked_stats(ranked_stats)
             ^^^^^^^^^^^^^^^^^^^^^^^^^^^^^^^^^
  File "C:\Users\cmerr\PycharmProjects\LeagueBot\src\utils\data_formatter.py", line 7, in format_ranked_stats
    for queue in ranked_stats:
                 ^^^^^^^^^^^^
TypeError: 'NoneType' object is not iterable

The above exception was the direct cause of the following exception:

Traceback (most recent call last):
  File "C:\Users\cmerr\AppData\Local\Packages\PythonSoftwareFoundation.Python.3.12_qbz5n2kfra8p0\LocalCache\local-packages\Python312\site-packages\discord\ext\commands\bot.py", line 1366, in invoke
    await ctx.command.invoke(ctx)
  File "C:\Users\cmerr\AppData\Local\Packages\PythonSoftwareFoundation.Python.3.12_qbz5n2kfra8p0\LocalCache\local-packages\Python312\site-packages\discord\ext\commands\core.py", line 1029, in invoke
    await injected(*ctx.args, **ctx.kwargs)  # type: ignore
    ^^^^^^^^^^^^^^^^^^^^^^^^^^^^^^^^^^^^^^^
  File "C:\Users\cmerr\AppData\Local\Packages\PythonSoftwareFoundation.Python.3.12_qbz5n2kfra8p0\LocalCache\local-packages\Python312\site-packages\discord\ext\commands\core.py", line 244, in wrapped
    raise CommandInvokeError(exc) from exc
discord.ext.commands.errors.CommandInvokeError: Command raised an exception: TypeError: 'NoneType' object is not iterable
INFO:__main__:HrwPKEHOCaydzW-l3MP-tIljgF_jKEYUSvXAxZ3dIB8d5moL3aE-P0-DoPFF8_5HtgrEZH7ozp7DPA
INFO:__main__:yOM00cNYd6DxMfbvwgsqsJVb9cRQrU2cxEcByt44XQyeKFU
INFO:__main__:None
INFO:__main__:None
ERROR:discord.ext.commands.bot:Ignoring exception in command stats
Traceback (most recent call last):
  File "C:\Users\cmerr\AppData\Local\Packages\PythonSoftwareFoundation.Python.3.12_qbz5n2kfra8p0\LocalCache\local-packages\Python312\site-packages\discord\ext\commands\core.py", line 235, in wrapped
    ret = await coro(*args, **kwargs)
          ^^^^^^^^^^^^^^^^^^^^^^^^^^^
  File "C:\Users\cmerr\PycharmProjects\LeagueBot\src\bot.py", line 62, in fetch_player_stats
    output = format_ranked_stats(ranked_stats)
             ^^^^^^^^^^^^^^^^^^^^^^^^^^^^^^^^^
  File "C:\Users\cmerr\PycharmProjects\LeagueBot\src\utils\data_formatter.py", line 7, in format_ranked_stats
    for queue in ranked_stats:
                 ^^^^^^^^^^^^
TypeError: 'NoneType' object is not iterable

The above exception was the direct cause of the following exception:

Traceback (most recent call last):
  File "C:\Users\cmerr\AppData\Local\Packages\PythonSoftwareFoundation.Python.3.12_qbz5n2kfra8p0\LocalCache\local-packages\Python312\site-packages\discord\ext\commands\bot.py", line 1366, in invoke
    await ctx.command.invoke(ctx)
  File "C:\Users\cmerr\AppData\Local\Packages\PythonSoftwareFoundation.Python.3.12_qbz5n2kfra8p0\LocalCache\local-packages\Python312\site-packages\discord\ext\commands\core.py", line 1029, in invoke
    await injected(*ctx.args, **ctx.kwargs)  # type: ignore
    ^^^^^^^^^^^^^^^^^^^^^^^^^^^^^^^^^^^^^^^
  File "C:\Users\cmerr\AppData\Local\Packages\PythonSoftwareFoundation.Python.3.12_qbz5n2kfra8p0\LocalCache\local-packages\Python312\site-packages\discord\ext\commands\core.py", line 244, in wrapped
    raise CommandInvokeError(exc) from exc
discord.ext.commands.errors.CommandInvokeError: Command raised an exception: TypeError: 'NoneType' object is not iterable
INFO:__main__:HrwPKEHOCaydzW-l3MP-tIljgF_jKEYUSvXAxZ3dIB8d5moL3aE-P0-DoPFF8_5HtgrEZH7ozp7DPA
INFO:__main__:yOM00cNYd6DxMfbvwgsqsJVb9cRQrU2cxEcByt44XQyeKFU
ERROR:discord.ext.commands.bot:Ignoring exception in command stats
Traceback (most recent call last):
  File "C:\Users\cmerr\AppData\Local\Packages\PythonSoftwareFoundation.Python.3.12_qbz5n2kfra8p0\LocalCache\local-packages\Python312\site-packages\discord\ext\commands\core.py", line 235, in wrapped
    ret = await coro(*args, **kwargs)
          ^^^^^^^^^^^^^^^^^^^^^^^^^^^
  File "C:\Users\cmerr\PycharmProjects\LeagueBot\src\bot.py", line 64, in fetch_player_stats
    await ctx.send(f'{username}"s stats:', end='')
          ^^^^^^^^^^^^^^^^^^^^^^^^^^^^^^^^^^^^^^^^
TypeError: Context.send() got an unexpected keyword argument 'end'

The above exception was the direct cause of the following exception:

Traceback (most recent call last):
  File "C:\Users\cmerr\AppData\Local\Packages\PythonSoftwareFoundation.Python.3.12_qbz5n2kfra8p0\LocalCache\local-packages\Python312\site-packages\discord\ext\commands\bot.py", line 1366, in invoke
    await ctx.command.invoke(ctx)
  File "C:\Users\cmerr\AppData\Local\Packages\PythonSoftwareFoundation.Python.3.12_qbz5n2kfra8p0\LocalCache\local-packages\Python312\site-packages\discord\ext\commands\core.py", line 1029, in invoke
    await injected(*ctx.args, **ctx.kwargs)  # type: ignore
    ^^^^^^^^^^^^^^^^^^^^^^^^^^^^^^^^^^^^^^^
  File "C:\Users\cmerr\AppData\Local\Packages\PythonSoftwareFoundation.Python.3.12_qbz5n2kfra8p0\LocalCache\local-packages\Python312\site-packages\discord\ext\commands\core.py", line 244, in wrapped
    raise CommandInvokeError(exc) from exc
discord.ext.commands.errors.CommandInvokeError: Command raised an exception: TypeError: Context.send() got an unexpected keyword argument 'end'
INFO:__main__:HrwPKEHOCaydzW-l3MP-tIljgF_jKEYUSvXAxZ3dIB8d5moL3aE-P0-DoPFF8_5HtgrEZH7ozp7DPA
INFO:__main__:yOM00cNYd6DxMfbvwgsqsJVb9cRQrU2cxEcByt44XQyeKFU
ERROR:discord.ext.commands.bot:Ignoring exception in command stats
Traceback (most recent call last):
  File "C:\Users\cmerr\AppData\Local\Packages\PythonSoftwareFoundation.Python.3.12_qbz5n2kfra8p0\LocalCache\local-packages\Python312\site-packages\discord\ext\commands\core.py", line 235, in wrapped
    ret = await coro(*args, **kwargs)
          ^^^^^^^^^^^^^^^^^^^^^^^^^^^
  File "C:\Users\cmerr\PycharmProjects\LeagueBot\src\bot.py", line 64, in fetch_player_stats
    await ctx.send(f'{username}"s stats:', end='')
          ^^^^^^^^^^^^^^^^^^^^^^^^^^^^^^^^^^^^^^^^
TypeError: Context.send() got an unexpected keyword argument 'end'

The above exception was the direct cause of the following exception:

Traceback (most recent call last):
  File "C:\Users\cmerr\AppData\Local\Packages\PythonSoftwareFoundation.Python.3.12_qbz5n2kfra8p0\LocalCache\local-packages\Python312\site-packages\discord\ext\commands\bot.py", line 1366, in invoke
    await ctx.command.invoke(ctx)
  File "C:\Users\cmerr\AppData\Local\Packages\PythonSoftwareFoundation.Python.3.12_qbz5n2kfra8p0\LocalCache\local-packages\Python312\site-packages\discord\ext\commands\core.py", line 1029, in invoke
    await injected(*ctx.args, **ctx.kwargs)  # type: ignore
    ^^^^^^^^^^^^^^^^^^^^^^^^^^^^^^^^^^^^^^^
  File "C:\Users\cmerr\AppData\Local\Packages\PythonSoftwareFoundation.Python.3.12_qbz5n2kfra8p0\LocalCache\local-packages\Python312\site-packages\discord\ext\commands\core.py", line 244, in wrapped
    raise CommandInvokeError(exc) from exc
discord.ext.commands.errors.CommandInvokeError: Command raised an exception: TypeError: Context.send() got an unexpected keyword argument 'end'
INFO:__main__:HrwPKEHOCaydzW-l3MP-tIljgF_jKEYUSvXAxZ3dIB8d5moL3aE-P0-DoPFF8_5HtgrEZH7ozp7DPA
INFO:__main__:yOM00cNYd6DxMfbvwgsqsJVb9cRQrU2cxEcByt44XQyeKFU
INFO:__main__:HrwPKEHOCaydzW-l3MP-tIljgF_jKEYUSvXAxZ3dIB8d5moL3aE-P0-DoPFF8_5HtgrEZH7ozp7DPA
INFO:__main__:yOM00cNYd6DxMfbvwgsqsJVb9cRQrU2cxEcByt44XQyeKFU
